KeyError: 'id'
Traceback:
File "/home/runner/workspace/.pythonlibs/lib/python3.11/site-packages/streamlit/runtime/scriptrunner/exec_code.py", line 121, in exec_func_with_error_handling
    result = func()
             ^^^^^^
File "/home/runner/workspace/.pythonlibs/lib/python3.11/site-packages/streamlit/runtime/scriptrunner/script_runner.py", line 643, in code_to_exec
    _mpa_v1(self._main_script_path)
File "/home/runner/workspace/.pythonlibs/lib/python3.11/site-packages/streamlit/runtime/scriptrunner/script_runner.py", line 164, in _mpa_v1
    page.run()
File "/home/runner/workspace/.pythonlibs/lib/python3.11/site-packages/streamlit/navigation/page.py", line 297, in run
    exec(code, module.__dict__)
File "/home/runner/workspace/pages/09_Sales_Analytics.py", line 408, in <module>
    main()
File "/home/runner/workspace/auth.py", line 159, in wrapper
    return func(*args, **kwargs)
           ^^^^^^^^^^^^^^^^^^^^^
File "/home/runner/workspace/pages/09_Sales_Analytics.py", line 347, in main
    customers_df['customer_label'] = customers_df.apply(
                                     ^^^^^^^^^^^^^^^^^^^
File "/home/runner/workspace/.pythonlibs/lib/python3.11/site-packages/pandas/core/frame.py", line 10374, in apply
    return op.apply().__finalize__(self, method="apply")
           ^^^^^^^^^^
File "/home/runner/workspace/.pythonlibs/lib/python3.11/site-packages/pandas/core/apply.py", line 916, in apply
    return self.apply_standard()
           ^^^^^^^^^^^^^^^^^^^^^
File "/home/runner/workspace/.pythonlibs/lib/python3.11/site-packages/pandas/core/apply.py", line 1063, in apply_standard
    results, res_index = self.apply_series_generator()
                         ^^^^^^^^^^^^^^^^^^^^^^^^^^^^^
File "/home/runner/workspace/.pythonlibs/lib/python3.11/site-packages/pandas/core/apply.py", line 1081, in apply_series_generator
    results[i] = self.func(v, *self.args, **self.kwargs)
                 ^^^^^^^^^^^^^^^^^^^^^^^^^^^^^^^^^^^^^^^
File "/home/runner/workspace/pages/09_Sales_Analytics.py", line 348, in <lambda>
    lambda x: f"{x.get('name', x.get('customer_name', 'Customer ' + str(x['id'])))}", axis=1
                                                                        ~^^^^^^
File "/home/runner/workspace/.pythonlibs/lib/python3.11/site-packages/pandas/core/series.py", line 1121, in __getitem__
    return self._get_value(key)
           ^^^^^^^^^^^^^^^^^^^^
File "/home/runner/workspace/.pythonlibs/lib/python3.11/site-packages/pandas/core/series.py", line 1237, in _get_value
    loc = self.index.get_loc(label)
          ^^^^^^^^^^^^^^^^^^^^^^^^^
File "/home/runner/workspace/.pythonlibs/lib/python3.11/site-packages/pandas/core/indexes/base.py", line 3812, in get_loc
    raise KeyError(key) from err